<?xml version="1.0" encoding="UTF-8"?>
<testsuite name="test_request_vaccine_tests.MyTestCase-20220316032022" tests="8" file="test_request_vaccine_tests.py" time="0.047" timestamp="2022-03-16T03:20:22" failures="0" errors="1" skipped="0">
	<testcase classname="test_request_vaccine_tests.MyTestCase" name="test_UUID_incorrecta" time="0.000" timestamp="2022-03-16T03:20:22"/>
	<testcase classname="test_request_vaccine_tests.MyTestCase" name="test_edad_inferior" time="0.000" timestamp="2022-03-16T03:20:22"/>
	<testcase classname="test_request_vaccine_tests.MyTestCase" name="test_edad_no_numero" time="0.016" timestamp="2022-03-16T03:20:22"/>
	<testcase classname="test_request_vaccine_tests.MyTestCase" name="test_edad_superior" time="0.000" timestamp="2022-03-16T03:20:22"/>
	<testcase classname="test_request_vaccine_tests.MyTestCase" name="test_nombre_largo" time="0.000" timestamp="2022-03-16T03:20:22"/>
	<testcase classname="test_request_vaccine_tests.MyTestCase" name="test_nombre_sin_apellido" time="0.000" timestamp="2022-03-16T03:20:22"/>
	<testcase classname="test_request_vaccine_tests.MyTestCase" name="test_nombre_vacio" time="0.000" timestamp="2022-03-16T03:20:22"/>
	<testcase classname="test_request_vaccine_tests.MyTestCase" name="test_registro_correcto" time="0.031" timestamp="2022-03-16T03:20:22">
		<error type="FileNotFoundError" message="[Errno 2] No such file or directory: 'C:\\Users\\talib/Desktop/G81.2022.15.E3/src/json/db/patient_registry.json'"><![CDATA[Traceback (most recent call last):
  File "C:\Users\talib\AppData\Local\Programs\Python\Python39\lib\unittest\case.py", line 59, in testPartExecutor
    yield
  File "C:\Users\talib\AppData\Local\Programs\Python\Python39\lib\unittest\case.py", line 592, in run
    self._callTestMethod(testMethod)
  File "C:\Users\talib\AppData\Local\Programs\Python\Python39\lib\unittest\case.py", line 550, in _callTestMethod
    method()
  File "c:\users\talib\desktop\g81.2022.15.e3\venv\lib\site-packages\freezegun\api.py", line 789, in wrapper
    result = func(*args, **kwargs)
  File "c:\users\talib\desktop\g81.2022.15.e3\src\unittest\python\test_request_vaccine_tests.py", line 87, in test_registro_correcto
    patient_id_test=vaccine_manager.request_vaccination_id(**patient)
  File "c:\users\talib\desktop\g81.2022.15.e3\src\main\python\uc3m_care\vaccine_manager.py", line 90, in request_vaccination_id
    with open(self.patient_registry, "r+",
FileNotFoundError: [Errno 2] No such file or directory: 'C:\\Users\\talib/Desktop/G81.2022.15.E3/src/json/db/patient_registry.json'
]]></error>
	</testcase>
</testsuite>
